Workbook

Sheet Sujet
A1: =+correction!A1 -> La société AERONEF fabrique et commercialise des avions. Elle souhaite développer des avions très innovants avec de nouvelles motorisations
A2: Composants | B2: Fonctions
A3: =+correction!A4 -> Carlingue | B3: =+correction!B4 -> Confort
A4: =+correction!A5 -> Moteur | B4: =+correction!B5 -> Vitesse
A5: =+correction!A6 -> Equipement électronique | B5: =+correction!B6 -> Facilité de Pilotage
A7: Prix cible TTC : | B7: =+correction!B8 -> 100000 | C7: TVA : | D7: 0.2
A8: Marge bénéficiaire attendue : | B8: =+correction!B9 -> 0.2 | C8: du prix de vente HT
A9: Degré d’importance des fonctions (analyse fonctionnelle) :
A10: Fonctions | B10: Pourcentage
A11: =B3 -> Confort | B11: =+correction!B12 -> 0.1
A12: =B4 -> Vitesse | B12: =+correction!B13 -> 0.3
A13: =B5 -> Facilité de Pilotage | B13: =+correction!B14 -> 0.6
A15: Contribution de chaque composant à la satisfaction des fonctions (résultats issus d'une étude de marché) :
A16: Fonctions | B16: Composants
B17: =+A3 -> Carlingue | C17: =+A4 -> Moteur | D17: =+A5 -> Equipement électronique
A18: =+A11 -> Confort | B18: 0.4 | C18: 0.1 | D18: 0.5
A19: =+A12 -> Vitesse | B19: 0.5 | C19: 0.1 | D19: 0.4
A20: =+A13 -> Facilité de Pilotage | B20: 0.2 | C20: 0.2 | D20: 0.6
A22: Coût estimé de chaque composant (résultats issus d'une analyse du bureau d'études de l'entreprise) :
B23: =+B17 -> Carlingue | C23: =+C17 -> Moteur | D23: =+D17 -> Equipement électronique | E23: Total
A24: Coût estimé | B24: =+correction!B25 -> 30000 | C24: =+correction!C25 -> 40000 | D24: =+correction!D25 -> 10000 | E24: =SUM(B24:D24) -> 80000
A26: Questions :
A27: 1) Calculez le coût cible
A28: 2) Déterminez la part de chaque composant dans la structure du coût cible
A29: 3) Calculez le coût cible par composant et évaluez l’écart avec le coût estimé
A30: 4) Commentez cet écart : que doit faire l'entreprise ?
A33: 1) Calculez le coût cible (1,5 points)
A39: 2) Déterminez la part en pourcentage de chaque composant dans la structure du coût cible (1 point)
A41: Fonctions | B41: Composants
B42: =B23 -> Carlingue | C42: =C23 -> Moteur | D42: =D23 -> Equipement électronique
A43: =B3 -> Confort
A45: =B4 -> Vitesse
A47: =B5 -> Facilité de Pilotage
A49: Total
A51: 3) Calculez le coût cible par composant et évaluez l’écart avec le coût estimé (1,5 points)
A52: Coût cible global =
A53: Coût estimé global =
A56: Composants | B56: Coût cible | D56: Coût estimé | E56: Ecart
B57: En % | C57: En euros | D57: En euros | E57: En euros
A58: =A3 -> Carlingue
...

Sheet correction
A1: La société AERONEF fabrique et commercialise des avions. Elle souhaite développer des avions très innovants avec de nouvelles motorisations
A2: Les données de l'étude sont :
A3: Composants | B3: Fonctions
A4: Carlingue | B4: Confort
A5: Moteur | B5: Vitesse
A6: Equipement électronique | B6: Facilité de Pilotage
A8: Prix cible TTC : | B8: 100000 | C8: TVA : | D8: 0.2
A9: Marge bénéficiaire attendue : | B9: 0.2 | C9: du prix de vente HT
A10: Degré d’importance des fonctions (analyse fonctionnelle) :
A11: Fonctions | B11: Pourcentage
A12: =B4 -> Confort | B12: 0.1
A13: =B5 -> Vitesse | B13: 0.3
A14: =B6 -> Facilité de Pilotage | B14: 0.6
A16: Contribution de chaque composant à la satisfaction des fonctions (résultats issus d'une étude de marché) :
A17: Fonctions | B17: Composants
B18: =+A4 -> Carlingue | C18: =+A5 -> Moteur | D18: =+A6 -> Equipement électronique
A19: =+A12 -> Confort | B19: 0.4 | C19: 0.1 | D19: 0.5
A20: =+A13 -> Vitesse | B20: 0.5 | C20: 0.1 | D20: 0.4
A21: =+A14 -> Facilité de Pilotage | B21: 0.2 | C21: 0.2 | D21: 0.6
A23: Coût estimé de chaque composant (résultats issus d'une analyse du bureau d'études de l'entreprise) :
B24: =+B18 -> Carlingue | C24: =+C18 -> Moteur | D24: =+D18 -> Equipement électronique | E24: Total
A25: Coût estimé | B25: 30000 | C25: 40000 | D25: 10000 | E25: =SUM(B25:D25) -> 80000
A27: Questions :
A28: 1) Calculez le coût cible
A29: 2) Déterminez la part de chaque composant dans la structure du coût cible
A30: 3) Calculez le coût cible par composant et évaluez l’écart avec le coût estimé
A31: 4) Commentez cet écart : que doit faire l'entreprise ?
A34: 1) Calculez le coût cible (1,5 points)
A35: Prix de vente | B35: – | C35: marge | F35: = | G35: = coût cible
A36: =+B8 -> 100000 | B36: – | C36: =+A36 -> 100000 | D36: x | E36: =+B9 -> 0.2 | F36: = | G36: =(A36/A37)-(C36/C37*E36) -> 66666.667
A37: =1+D8 -> 1.2 | C37: =+A37 -> 1.2
A40: 2) Déterminez la part en pourcentage de chaque composant dans la structure du coût cible (1 point)
A42: Fonctions | B42: Composants
B43: =B24 -> Carlingue | C43: =C24 -> Moteur | D43: =D24 -> Equipement électronique
A44: =B4 -> Confort | B44: =B12*B19 -> 0.04 | C44: =B12*C19 -> 0.01 | D44: =B12*D19 -> 0.05
A45: =B5 -> Vitesse | B45: =B13*B20 -> 0.15 | C45: =+B13*C20 -> 0.03 | D45: =B13*D20 -> 0.12
A46: =B6 -> Facilité de Pilotage | B46: =B14*B21 -> 0.12 | C46: =B14*C21 -> 0.12 | D46: =B14*D21 -> 0.36
A47: Total | B47: =SUM(B44+B45+B46) -> 0.31 | C47: =SUM(C44+C45+C46) -> 0.16 | D47: =SUM(D44+D45+D46) -> 0.53
A49: 3) Calculez le coût cible par composant et évaluez l’écart avec le coût estimé (1,5 points)
A50: Coût cible global = | B50: =+G36 -> 66666.667
...
